2021-08-03 10:36:56,369 - H:\python3.8.2\lib\asyncio\proactor_events.py[line:623] - DEBUG: Using proactor: IocpProactor
2021-08-03 10:39:24,632 - H:\python3.8.2\lib\asyncio\proactor_events.py[line:623] - DEBUG: Using proactor: IocpProactor
2021-08-03 10:39:28,853 - H:/pycharm/0pycharm_project/flow_agent_system_server/traffic_forwarding/client/client/TCP_echo_client.py[line:217] - ERROR: 与服务器的连接已断开！
2021-08-03 10:44:08,153 - H:\python3.8.2\lib\asyncio\proactor_events.py[line:623] - DEBUG: Using proactor: IocpProactor
2021-08-03 10:44:09,163 - H:/pycharm/0pycharm_project/flow_agent_system_server/traffic_forwarding/client/client/TCP_echo_client.py[line:220] - INFO: 目标服务器未开启...请重试
2021-08-03 10:44:17,153 - H:\python3.8.2\lib\asyncio\proactor_events.py[line:623] - DEBUG: Using proactor: IocpProactor
2021-08-03 10:44:21,253 - H:/pycharm/0pycharm_project/flow_agent_system_server/traffic_forwarding/client/client/TCP_echo_client.py[line:226] - INFO: 与服务器的连接已断开
2021-08-03 11:07:51,343 - H:\python3.8.2\lib\asyncio\proactor_events.py[line:623] - DEBUG: Using proactor: IocpProactor
2021-08-03 11:12:24,203 - H:/pycharm/0pycharm_project/flow_agent_system_server/traffic_forwarding/client/client/TCP_echo_client.py[line:204] - INFO: 与服务器的连接已断开
2021-08-03 14:54:50,921 - H:\python3.8.2\lib\asyncio\proactor_events.py[line:623] - DEBUG: Using proactor: IocpProactor
2021-08-03 14:58:57,268 - H:\python3.8.2\lib\asyncio\proactor_events.py[line:623] - DEBUG: Using proactor: IocpProactor
2021-08-03 15:11:26,505 - H:\python3.8.2\lib\asyncio\proactor_events.py[line:623] - DEBUG: Using proactor: IocpProactor
2021-08-03 15:13:39,511 - H:\python3.8.2\lib\asyncio\proactor_events.py[line:623] - DEBUG: Using proactor: IocpProactor
2021-08-03 15:15:18,907 - H:\python3.8.2\lib\asyncio\proactor_events.py[line:623] - DEBUG: Using proactor: IocpProactor
2021-08-03 15:22:27,887 - H:\python3.8.2\lib\asyncio\proactor_events.py[line:623] - DEBUG: Using proactor: IocpProactor
2021-08-03 15:49:48,597 - H:\python3.8.2\lib\asyncio\proactor_events.py[line:623] - DEBUG: Using proactor: IocpProactor
2021-08-03 15:52:02,397 - H:\python3.8.2\lib\asyncio\proactor_events.py[line:623] - DEBUG: Using proactor: IocpProactor
2021-08-03 16:07:03,596 - H:\python3.8.2\lib\asyncio\proactor_events.py[line:623] - DEBUG: Using proactor: IocpProactor
2021-08-03 16:14:00,298 - H:\python3.8.2\lib\asyncio\proactor_events.py[line:623] - DEBUG: Using proactor: IocpProactor
2021-08-03 16:34:50,215 - H:\python3.8.2\lib\asyncio\proactor_events.py[line:623] - DEBUG: Using proactor: IocpProactor
2021-08-03 16:57:39,198 - H:\python3.8.2\lib\asyncio\proactor_events.py[line:623] - DEBUG: Using proactor: IocpProactor
2021-08-03 17:01:50,062 - H:\python3.8.2\lib\asyncio\proactor_events.py[line:623] - DEBUG: Using proactor: IocpProactor
2021-08-03 18:14:33,571 - H:\python3.8.2\lib\asyncio\proactor_events.py[line:623] - DEBUG: Using proactor: IocpProactor
2021-08-03 19:35:21,888 - H:\python3.8.2\lib\asyncio\proactor_events.py[line:623] - DEBUG: Using proactor: IocpProactor
2021-08-03 20:05:39,381 - H:/pycharm/0pycharm_project/flow_agent_system_server/traffic_forwarding/client/client/TCP_echo_client.py[line:204] - INFO: 与服务器的连接已断开
2021-08-03 20:05:45,478 - H:\python3.8.2\lib\asyncio\proactor_events.py[line:623] - DEBUG: Using proactor: IocpProactor
2021-08-03 20:09:14,157 - H:\python3.8.2\lib\asyncio\proactor_events.py[line:623] - DEBUG: Using proactor: IocpProactor
2021-08-03 20:26:18,243 - H:\python3.8.2\lib\asyncio\proactor_events.py[line:623] - DEBUG: Using proactor: IocpProactor
2021-08-03 20:30:07,672 - H:\python3.8.2\lib\asyncio\proactor_events.py[line:623] - DEBUG: Using proactor: IocpProactor
2021-08-03 20:32:15,001 - H:\python3.8.2\lib\asyncio\proactor_events.py[line:623] - DEBUG: Using proactor: IocpProactor
2021-08-03 20:35:37,305 - H:\python3.8.2\lib\asyncio\proactor_events.py[line:623] - DEBUG: Using proactor: IocpProactor
2021-08-03 20:37:01,521 - H:\python3.8.2\lib\asyncio\base_events.py[line:1707] - ERROR: Task exception was never retrieved
future: <Task finished name='Task-7' coro=<port_transmit_other() done, defined at H:/pycharm/0pycharm_project/flow_agent_system_server/traffic_forwarding/client/client/TCP_echo_client.py:80> exception=UnicodeDecodeError('utf-8', b'\x00\x00\x04\xc4\x05\x14\xa1\x96GA\xf2Q\x0fJC\xa8g\xd3\x88z\xc0\xc4\x00\x00\x010curve25519-sha256,curve25519-sha256@libssh.org,ecdh-sha2-nistp256,ecdh-sha2-nistp384,ecdh-sha2-nistp521,diffie-hellman-group-exchange-sha256,diffie-hellman-group16-sha512,diffie-hellman-group18-sha512,diffie-hellman-group-exchange-sha1,diffie-hellman-group14-sha256,diffie-hellman-group14-sha1,ext-info-c\x00\x00\x01"ecdsa-sha2-nistp256-cert-v01@openssh.com,ecdsa-sha2-nistp384-cert-v01@openssh.com,ecdsa-sha2-nistp521-cert-v01@openssh.com,ecdsa-sha2-nistp256,ecdsa-sha2-nistp384,ecdsa-sha2-nistp521,ssh-ed25519-cert-v01@openssh.com,ssh-rsa-cert-v01@openssh.com,ssh-ed25519,rsa-sha2-512,rsa-sha2-256,ssh-rsa\x00\x00\x00>chacha20-poly1305@openssh.com,aes128-ctr,aes192-ctr,aes256-ctr\x00\x00\x00>chacha20-poly1305@openssh.com,aes128-ctr,aes192-ctr,aes256-ctr\x00\x00\x00\xd5umac-64-etm@openssh.com,umac-128-etm@openssh.com,hmac-sha2-256-etm@openssh.com,hmac-sha2-512-etm@openssh.com,hmac-sha1-etm@openssh.com,umac-64@openssh.com,umac-128@openssh.com,hmac-sha2-256,hmac-sha2-512,hmac-sha1\x00\x00\x00\xd5umac-64-etm@openssh.com,umac-128-etm@openssh.com,hmac-sha2-256-etm@openssh.com,hmac-sha2-512-etm@openssh.com,hmac-sha1-etm@openssh.com,umac-64@openssh.com,umac-128@openssh.com,hmac-sha2-256,hmac-sha2-512,hmac-sha1\x00\x00\x00\x04none\x00\x00\x00\x04none\x00\x00\x00\x00\x00\x00\x00\x00\x00\x00\x00\x00\x00\x00\x00\x00\x00\x00', 3, 4, 'invalid continuation byte')>
Traceback (most recent call last):
  File "H:/pycharm/0pycharm_project/flow_agent_system_server/traffic_forwarding/client/client/TCP_echo_client.py", line 85, in port_transmit_other
    data = data.decode()
UnicodeDecodeError: 'utf-8' codec can't decode byte 0xc4 in position 3: invalid continuation byte
2021-08-03 20:42:37,792 - H:\python3.8.2\lib\asyncio\proactor_events.py[line:623] - DEBUG: Using proactor: IocpProactor
2021-08-03 20:43:35,816 - H:\python3.8.2\lib\asyncio\proactor_events.py[line:623] - DEBUG: Using proactor: IocpProactor
2021-08-03 20:49:14,001 - H:\python3.8.2\lib\asyncio\proactor_events.py[line:623] - DEBUG: Using proactor: IocpProactor
2021-08-03 20:49:48,732 - H:\python3.8.2\lib\asyncio\proactor_events.py[line:623] - DEBUG: Using proactor: IocpProactor
2021-08-03 20:53:53,336 - H:\python3.8.2\lib\asyncio\base_events.py[line:1707] - ERROR: Task exception was never retrieved
future: <Task finished name='Task-7' coro=<port_transmit_other() done, defined at H:/pycharm/0pycharm_project/flow_agent_system_server/traffic_forwarding/client/client/TCP_echo_client.py:80> exception=UnicodeDecodeError('utf-8', b'\x00\x00\x04\xc4\x05\x14\xa7\xfb+\x0e\x8a\x9d\xd2\x89\xf0\xccl\x8d\xe1z/\xfb\x00\x00\x010curve25519-sha256,curve25519-sha256@libssh.org,ecdh-sha2-nistp256,ecdh-sha2-nistp384,ecdh-sha2-nistp521,diffie-hellman-group-exchange-sha256,diffie-hellman-group16-sha512,diffie-hellman-group18-sha512,diffie-hellman-group-exchange-sha1,diffie-hellman-group14-sha256,diffie-hellman-group14-sha1,ext-info-c\x00\x00\x01"ecdsa-sha2-nistp256-cert-v01@openssh.com,ecdsa-sha2-nistp384-cert-v01@openssh.com,ecdsa-sha2-nistp521-cert-v01@openssh.com,ssh-ed25519-cert-v01@openssh.com,ssh-rsa-cert-v01@openssh.com,ecdsa-sha2-nistp256,ecdsa-sha2-nistp384,ecdsa-sha2-nistp521,ssh-ed25519,rsa-sha2-512,rsa-sha2-256,ssh-rsa\x00\x00\x00>chacha20-poly1305@openssh.com,aes128-ctr,aes192-ctr,aes256-ctr\x00\x00\x00>chacha20-poly1305@openssh.com,aes128-ctr,aes192-ctr,aes256-ctr\x00\x00\x00\xd5umac-64-etm@openssh.com,umac-128-etm@openssh.com,hmac-sha2-256-etm@openssh.com,hmac-sha2-512-etm@openssh.com,hmac-sha1-etm@openssh.com,umac-64@openssh.com,umac-128@openssh.com,hmac-sha2-256,hmac-sha2-512,hmac-sha1\x00\x00\x00\xd5umac-64-etm@openssh.com,umac-128-etm@openssh.com,hmac-sha2-256-etm@openssh.com,hmac-sha2-512-etm@openssh.com,hmac-sha1-etm@openssh.com,umac-64@openssh.com,umac-128@openssh.com,hmac-sha2-256,hmac-sha2-512,hmac-sha1\x00\x00\x00\x04none\x00\x00\x00\x04none\x00\x00\x00\x00\x00\x00\x00\x00\x00\x00\x00\x00\x00\x00\x00\x00\x00\x00', 3, 4, 'invalid continuation byte')>
Traceback (most recent call last):
  File "H:/pycharm/0pycharm_project/flow_agent_system_server/traffic_forwarding/client/client/TCP_echo_client.py", line 85, in port_transmit_other
    data = data.decode()
UnicodeDecodeError: 'utf-8' codec can't decode byte 0xc4 in position 3: invalid continuation byte
2021-08-03 21:06:05,490 - H:\python3.8.2\lib\asyncio\proactor_events.py[line:623] - DEBUG: Using proactor: IocpProactor
2021-08-03 21:07:33,590 - H:\python3.8.2\lib\asyncio\proactor_events.py[line:623] - DEBUG: Using proactor: IocpProactor
2021-08-03 21:12:17,767 - H:\python3.8.2\lib\asyncio\base_events.py[line:1707] - ERROR: Task exception was never retrieved
future: <Task finished name='Task-7' coro=<port_transmit_other() done, defined at H:/pycharm/0pycharm_project/flow_agent_system_server/traffic_forwarding/client/client/TCP_echo_client.py:80> exception=UnicodeDecodeError('utf-8', b'\x00\x00\x04\xc4\x05\x14\x7f\x1cd\xd9\xa6z\xe5\xd7W\x1fw\x96\xedy\xb8\xdc\x00\x00\x010curve25519-sha256,curve25519-sha256@libssh.org,ecdh-sha2-nistp256,ecdh-sha2-nistp384,ecdh-sha2-nistp521,diffie-hellman-group-exchange-sha256,diffie-hellman-group16-sha512,diffie-hellman-group18-sha512,diffie-hellman-group-exchange-sha1,diffie-hellman-group14-sha256,diffie-hellman-group14-sha1,ext-info-c\x00\x00\x01"ecdsa-sha2-nistp256-cert-v01@openssh.com,ecdsa-sha2-nistp384-cert-v01@openssh.com,ecdsa-sha2-nistp521-cert-v01@openssh.com,ssh-ed25519-cert-v01@openssh.com,ssh-rsa-cert-v01@openssh.com,ecdsa-sha2-nistp256,ecdsa-sha2-nistp384,ecdsa-sha2-nistp521,ssh-ed25519,rsa-sha2-512,rsa-sha2-256,ssh-rsa\x00\x00\x00>chacha20-poly1305@openssh.com,aes128-ctr,aes192-ctr,aes256-ctr\x00\x00\x00>chacha20-poly1305@openssh.com,aes128-ctr,aes192-ctr,aes256-ctr\x00\x00\x00\xd5umac-64-etm@openssh.com,umac-128-etm@openssh.com,hmac-sha2-256-etm@openssh.com,hmac-sha2-512-etm@openssh.com,hmac-sha1-etm@openssh.com,umac-64@openssh.com,umac-128@openssh.com,hmac-sha2-256,hmac-sha2-512,hmac-sha1\x00\x00\x00\xd5umac-64-etm@openssh.com,umac-128-etm@openssh.com,hmac-sha2-256-etm@openssh.com,hmac-sha2-512-etm@openssh.com,hmac-sha1-etm@openssh.com,umac-64@openssh.com,umac-128@openssh.com,hmac-sha2-256,hmac-sha2-512,hmac-sha1\x00\x00\x00\x04none\x00\x00\x00\x04none\x00\x00\x00\x00\x00\x00\x00\x00\x00\x00\x00\x00\x00\x00\x00\x00\x00\x00', 3, 4, 'invalid continuation byte')>
Traceback (most recent call last):
  File "H:/pycharm/0pycharm_project/flow_agent_system_server/traffic_forwarding/client/client/TCP_echo_client.py", line 85, in port_transmit_other
    data = data.decode()
UnicodeDecodeError: 'utf-8' codec can't decode byte 0xc4 in position 3: invalid continuation byte
2021-08-03 21:14:03,031 - H:\python3.8.2\lib\asyncio\proactor_events.py[line:623] - DEBUG: Using proactor: IocpProactor
2021-08-03 21:15:05,917 - H:\python3.8.2\lib\asyncio\base_events.py[line:1707] - ERROR: Task exception was never retrieved
future: <Task finished name='Task-7' coro=<port_transmit_other() done, defined at H:/pycharm/0pycharm_project/flow_agent_system_server/traffic_forwarding/client/client/TCP_echo_client.py:80> exception=UnicodeDecodeError('utf-8', b'\x00\x00\x04\xc4\x05\x14\xa3)\xd0Q\x9cz\nd\xe0\x98\x03p\xf0y\x95\xe0\x00\x00\x010curve25519-sha256,curve25519-sha256@libssh.org,ecdh-sha2-nistp256,ecdh-sha2-nistp384,ecdh-sha2-nistp521,diffie-hellman-group-exchange-sha256,diffie-hellman-group16-sha512,diffie-hellman-group18-sha512,diffie-hellman-group-exchange-sha1,diffie-hellman-group14-sha256,diffie-hellman-group14-sha1,ext-info-c\x00\x00\x01"ecdsa-sha2-nistp256-cert-v01@openssh.com,ecdsa-sha2-nistp384-cert-v01@openssh.com,ecdsa-sha2-nistp521-cert-v01@openssh.com,ecdsa-sha2-nistp256,ecdsa-sha2-nistp384,ecdsa-sha2-nistp521,ssh-ed25519-cert-v01@openssh.com,ssh-rsa-cert-v01@openssh.com,ssh-ed25519,rsa-sha2-512,rsa-sha2-256,ssh-rsa\x00\x00\x00>chacha20-poly1305@openssh.com,aes128-ctr,aes192-ctr,aes256-ctr\x00\x00\x00>chacha20-poly1305@openssh.com,aes128-ctr,aes192-ctr,aes256-ctr\x00\x00\x00\xd5umac-64-etm@openssh.com,umac-128-etm@openssh.com,hmac-sha2-256-etm@openssh.com,hmac-sha2-512-etm@openssh.com,hmac-sha1-etm@openssh.com,umac-64@openssh.com,umac-128@openssh.com,hmac-sha2-256,hmac-sha2-512,hmac-sha1\x00\x00\x00\xd5umac-64-etm@openssh.com,umac-128-etm@openssh.com,hmac-sha2-256-etm@openssh.com,hmac-sha2-512-etm@openssh.com,hmac-sha1-etm@openssh.com,umac-64@openssh.com,umac-128@openssh.com,hmac-sha2-256,hmac-sha2-512,hmac-sha1\x00\x00\x00\x04none\x00\x00\x00\x04none\x00\x00\x00\x00\x00\x00\x00\x00\x00\x00\x00\x00\x00\x00\x00\x00\x00\x00', 3, 4, 'invalid continuation byte')>
Traceback (most recent call last):
  File "H:/pycharm/0pycharm_project/flow_agent_system_server/traffic_forwarding/client/client/TCP_echo_client.py", line 85, in port_transmit_other
    data = data.decode()
UnicodeDecodeError: 'utf-8' codec can't decode byte 0xc4 in position 3: invalid continuation byte
2021-08-04 09:01:36,059 - H:\python3.8.2\lib\asyncio\proactor_events.py[line:623] - DEBUG: Using proactor: IocpProactor
2021-08-04 09:03:36,439 - H:\python3.8.2\lib\asyncio\base_events.py[line:1707] - ERROR: Task exception was never retrieved
future: <Task finished name='Task-7' coro=<port_transmit_other() done, defined at H:/pycharm/0pycharm_project/flow_agent_system_server/traffic_forwarding/client/client/TCP_echo_client.py:80> exception=UnicodeDecodeError('utf-8', b'\x00\x00\x04\xc4\x05\x14\x06V\xb4\x87\xbec\xcf~\xe4F\x16A*z\x8e\x03\x00\x00\x010curve25519-sha256,curve25519-sha256@libssh.org,ecdh-sha2-nistp256,ecdh-sha2-nistp384,ecdh-sha2-nistp521,diffie-hellman-group-exchange-sha256,diffie-hellman-group16-sha512,diffie-hellman-group18-sha512,diffie-hellman-group-exchange-sha1,diffie-hellman-group14-sha256,diffie-hellman-group14-sha1,ext-info-c\x00\x00\x01"ecdsa-sha2-nistp256-cert-v01@openssh.com,ecdsa-sha2-nistp384-cert-v01@openssh.com,ecdsa-sha2-nistp521-cert-v01@openssh.com,ecdsa-sha2-nistp256,ecdsa-sha2-nistp384,ecdsa-sha2-nistp521,ssh-ed25519-cert-v01@openssh.com,ssh-rsa-cert-v01@openssh.com,ssh-ed25519,rsa-sha2-512,rsa-sha2-256,ssh-rsa\x00\x00\x00>chacha20-poly1305@openssh.com,aes128-ctr,aes192-ctr,aes256-ctr\x00\x00\x00>chacha20-poly1305@openssh.com,aes128-ctr,aes192-ctr,aes256-ctr\x00\x00\x00\xd5umac-64-etm@openssh.com,umac-128-etm@openssh.com,hmac-sha2-256-etm@openssh.com,hmac-sha2-512-etm@openssh.com,hmac-sha1-etm@openssh.com,umac-64@openssh.com,umac-128@openssh.com,hmac-sha2-256,hmac-sha2-512,hmac-sha1\x00\x00\x00\xd5umac-64-etm@openssh.com,umac-128-etm@openssh.com,hmac-sha2-256-etm@openssh.com,hmac-sha2-512-etm@openssh.com,hmac-sha1-etm@openssh.com,umac-64@openssh.com,umac-128@openssh.com,hmac-sha2-256,hmac-sha2-512,hmac-sha1\x00\x00\x00\x04none\x00\x00\x00\x04none\x00\x00\x00\x00\x00\x00\x00\x00\x00\x00\x00\x00\x00\x00\x00\x00\x00\x00', 3, 4, 'invalid continuation byte')>
Traceback (most recent call last):
  File "H:/pycharm/0pycharm_project/flow_agent_system_server/traffic_forwarding/client/client/TCP_echo_client.py", line 85, in port_transmit_other
    data = data.decode()
UnicodeDecodeError: 'utf-8' codec can't decode byte 0xc4 in position 3: invalid continuation byte
2021-08-04 09:15:32,232 - H:\python3.8.2\lib\asyncio\proactor_events.py[line:623] - DEBUG: Using proactor: IocpProactor
2021-08-04 09:17:47,019 - H:\python3.8.2\lib\asyncio\proactor_events.py[line:623] - DEBUG: Using proactor: IocpProactor
2021-08-04 09:18:30,149 - H:\python3.8.2\lib\asyncio\proactor_events.py[line:623] - DEBUG: Using proactor: IocpProactor
2021-08-04 09:19:35,504 - H:\python3.8.2\lib\asyncio\base_events.py[line:1707] - ERROR: Task exception was never retrieved
future: <Task finished name='Task-7' coro=<port_transmit_other() done, defined at H:/pycharm/0pycharm_project/flow_agent_system_server/traffic_forwarding/client/client/TCP_echo_client.py:80> exception=UnicodeDecodeError('utf-8', b'\x00\x00\x04\xc4\x05\x14z\xa7\xf1\x85T\xed`aU\xfeze\xd6W\xe3v\x00\x00\x010curve25519-sha256,curve25519-sha256@libssh.org,ecdh-sha2-nistp256,ecdh-sha2-nistp384,ecdh-sha2-nistp521,diffie-hellman-group-exchange-sha256,diffie-hellman-group16-sha512,diffie-hellman-group18-sha512,diffie-hellman-group-exchange-sha1,diffie-hellman-group14-sha256,diffie-hellman-group14-sha1,ext-info-c\x00\x00\x01"ecdsa-sha2-nistp256-cert-v01@openssh.com,ecdsa-sha2-nistp384-cert-v01@openssh.com,ecdsa-sha2-nistp521-cert-v01@openssh.com,ecdsa-sha2-nistp256,ecdsa-sha2-nistp384,ecdsa-sha2-nistp521,ssh-ed25519-cert-v01@openssh.com,ssh-rsa-cert-v01@openssh.com,ssh-ed25519,rsa-sha2-512,rsa-sha2-256,ssh-rsa\x00\x00\x00>chacha20-poly1305@openssh.com,aes128-ctr,aes192-ctr,aes256-ctr\x00\x00\x00>chacha20-poly1305@openssh.com,aes128-ctr,aes192-ctr,aes256-ctr\x00\x00\x00\xd5umac-64-etm@openssh.com,umac-128-etm@openssh.com,hmac-sha2-256-etm@openssh.com,hmac-sha2-512-etm@openssh.com,hmac-sha1-etm@openssh.com,umac-64@openssh.com,umac-128@openssh.com,hmac-sha2-256,hmac-sha2-512,hmac-sha1\x00\x00\x00\xd5umac-64-etm@openssh.com,umac-128-etm@openssh.com,hmac-sha2-256-etm@openssh.com,hmac-sha2-512-etm@openssh.com,hmac-sha1-etm@openssh.com,umac-64@openssh.com,umac-128@openssh.com,hmac-sha2-256,hmac-sha2-512,hmac-sha1\x00\x00\x00\x04none\x00\x00\x00\x04none\x00\x00\x00\x00\x00\x00\x00\x00\x00\x00\x00\x00\x00\x00\x00\x00\x00\x00', 3, 4, 'invalid continuation byte')>
Traceback (most recent call last):
  File "H:/pycharm/0pycharm_project/flow_agent_system_server/traffic_forwarding/client/client/TCP_echo_client.py", line 85, in port_transmit_other
    data = data.decode()
UnicodeDecodeError: 'utf-8' codec can't decode byte 0xc4 in position 3: invalid continuation byte
2021-08-04 09:28:46,378 - H:\python3.8.2\lib\asyncio\proactor_events.py[line:623] - DEBUG: Using proactor: IocpProactor
